[2025-01-28T08:21:13.574+0000] {local_task_job_runner.py:120} INFO - ::group::Pre task execution logs
[2025-01-28T08:21:13.601+0000] {taskinstance.py:2076} INFO - Dependencies all met for dep_context=non-requeueable deps ti=<TaskInstance: order_analysis_dag.load scheduled__2024-06-18T00:00:00+00:00 [queued]>
[2025-01-28T08:21:13.608+0000] {taskinstance.py:2076} INFO - Dependencies all met for dep_context=requeueable deps ti=<TaskInstance: order_analysis_dag.load scheduled__2024-06-18T00:00:00+00:00 [queued]>
[2025-01-28T08:21:13.608+0000] {taskinstance.py:2306} INFO - Starting attempt 1 of 11
[2025-01-28T08:21:13.619+0000] {taskinstance.py:2330} INFO - Executing <Task(_PythonDecoratedOperator): load> on 2024-06-18 00:00:00+00:00
[2025-01-28T08:21:13.626+0000] {logging_mixin.py:188} WARNING - /home/***/.local/lib/python3.12/site-packages/***/task/task_runner/standard_task_runner.py:61 DeprecationWarning: This process (pid=294) is multi-threaded, use of fork() may lead to deadlocks in the child.
[2025-01-28T08:21:13.627+0000] {standard_task_runner.py:63} INFO - Started process 313 to run task
[2025-01-28T08:21:13.627+0000] {standard_task_runner.py:90} INFO - Running: ['***', 'tasks', 'run', 'order_analysis_dag', 'load', 'scheduled__2024-06-18T00:00:00+00:00', '--job-id', '27', '--raw', '--subdir', 'DAGS_FOLDER/order_analysis_dag.py', '--cfg-path', '/tmp/tmp6ql6nd39']
[2025-01-28T08:21:13.633+0000] {standard_task_runner.py:91} INFO - Job 27: Subtask load
[2025-01-28T08:21:13.658+0000] {logging_mixin.py:188} WARNING - /home/***/.local/lib/python3.12/site-packages/***/settings.py:195 DeprecationWarning: The sql_alchemy_conn option in [core] has been moved to the sql_alchemy_conn option in [database] - the old setting has been used, but please update your config.
[2025-01-28T08:21:13.703+0000] {task_command.py:426} INFO - Running <TaskInstance: order_analysis_dag.load scheduled__2024-06-18T00:00:00+00:00 [running]> on host a32532c03133
[2025-01-28T08:21:13.770+0000] {taskinstance.py:2648} INFO - Exporting env vars: AIRFLOW_CTX_DAG_OWNER='***' AIRFLOW_CTX_DAG_ID='order_analysis_dag' AIRFLOW_CTX_TASK_ID='load' AIRFLOW_CTX_EXECUTION_DATE='2024-06-18T00:00:00+00:00' AIRFLOW_CTX_TRY_NUMBER='1' AIRFLOW_CTX_DAG_RUN_ID='scheduled__2024-06-18T00:00:00+00:00'
[2025-01-28T08:21:13.772+0000] {taskinstance.py:430} INFO - ::endgroup::
[2025-01-28T08:21:14.093+0000] {taskinstance.py:441} INFO - ::group::Post task execution logs
[2025-01-28T08:21:14.094+0000] {taskinstance.py:2905} ERROR - Task failed with exception
Traceback (most recent call last):
  File "/home/airflow/.local/lib/python3.12/site-packages/sqlalchemy/engine/base.py", line 1094, in _commit_impl
    self.engine.dialect.do_commit(self.connection)
  File "/home/airflow/.local/lib/python3.12/site-packages/sqlalchemy/engine/default.py", line 686, in do_commit
    dbapi_connection.commit()
sqlite3.OperationalError: disk I/O error

The above exception was the direct cause of the following exception:

Traceback (most recent call last):
  File "/home/airflow/.local/lib/python3.12/site-packages/airflow/models/taskinstance.py", line 465, in _execute_task
    result = _execute_callable(context=context, **execute_callable_kwargs)
             ^^^^^^^^^^^^^^^^^^^^^^^^^^^^^^^^^^^^^^^^^^^^^^^^^^^^^^^^^^^^^
  File "/home/airflow/.local/lib/python3.12/site-packages/airflow/models/taskinstance.py", line 432, in _execute_callable
    return execute_callable(context=context, **execute_callable_kwargs)
           ^^^^^^^^^^^^^^^^^^^^^^^^^^^^^^^^^^^^^^^^^^^^^^^^^^^^^^^^^^^^
  File "/home/airflow/.local/lib/python3.12/site-packages/airflow/models/baseoperator.py", line 400, in wrapper
    return func(self, *args, **kwargs)
           ^^^^^^^^^^^^^^^^^^^^^^^^^^^
  File "/home/airflow/.local/lib/python3.12/site-packages/airflow/decorators/base.py", line 265, in execute
    return_value = super().execute(context)
                   ^^^^^^^^^^^^^^^^^^^^^^^^
  File "/home/airflow/.local/lib/python3.12/site-packages/airflow/models/baseoperator.py", line 400, in wrapper
    return func(self, *args, **kwargs)
           ^^^^^^^^^^^^^^^^^^^^^^^^^^^
  File "/home/airflow/.local/lib/python3.12/site-packages/airflow/operators/python.py", line 235, in execute
    return_value = self.execute_callable()
                   ^^^^^^^^^^^^^^^^^^^^^^^
  File "/home/airflow/.local/lib/python3.12/site-packages/airflow/operators/python.py", line 252, in execute_callable
    return self.python_callable(*self.op_args, **self.op_kwargs)
           ^^^^^^^^^^^^^^^^^^^^^^^^^^^^^^^^^^^^^^^^^^^^^^^^^^^^^
  File "/opt/airflow/dags/order_analysis_dag.py", line 114, in load
    upsert(conn, final_data_table, transformed_data)
  File "/opt/airflow/dags/order_analysis_dag.py", line 194, in upsert
    conn.execute(stmt)
  File "/home/airflow/.local/lib/python3.12/site-packages/sqlalchemy/engine/base.py", line 1385, in execute
    return meth(self, multiparams, params, _EMPTY_EXECUTION_OPTS)
           ^^^^^^^^^^^^^^^^^^^^^^^^^^^^^^^^^^^^^^^^^^^^^^^^^^^^^^
  File "/home/airflow/.local/lib/python3.12/site-packages/sqlalchemy/sql/elements.py", line 334, in _execute_on_connection
    return connection._execute_clauseelement(
           ^^^^^^^^^^^^^^^^^^^^^^^^^^^^^^^^^^
  File "/home/airflow/.local/lib/python3.12/site-packages/sqlalchemy/engine/base.py", line 1577, in _execute_clauseelement
    ret = self._execute_context(
          ^^^^^^^^^^^^^^^^^^^^^^
  File "/home/airflow/.local/lib/python3.12/site-packages/sqlalchemy/engine/base.py", line 1953, in _execute_context
    self._handle_dbapi_exception(
  File "/home/airflow/.local/lib/python3.12/site-packages/sqlalchemy/engine/base.py", line 2138, in _handle_dbapi_exception
    util.raise_(exc_info[1], with_traceback=exc_info[2])
  File "/home/airflow/.local/lib/python3.12/site-packages/sqlalchemy/util/compat.py", line 211, in raise_
    raise exception
  File "/home/airflow/.local/lib/python3.12/site-packages/sqlalchemy/engine/base.py", line 1940, in _execute_context
    self._commit_impl(autocommit=True)
  File "/home/airflow/.local/lib/python3.12/site-packages/sqlalchemy/engine/base.py", line 1096, in _commit_impl
    self._handle_dbapi_exception(e, None, None, None, None)
  File "/home/airflow/.local/lib/python3.12/site-packages/sqlalchemy/engine/base.py", line 2134, in _handle_dbapi_exception
    util.raise_(
  File "/home/airflow/.local/lib/python3.12/site-packages/sqlalchemy/util/compat.py", line 211, in raise_
    raise exception
  File "/home/airflow/.local/lib/python3.12/site-packages/sqlalchemy/engine/base.py", line 1094, in _commit_impl
    self.engine.dialect.do_commit(self.connection)
  File "/home/airflow/.local/lib/python3.12/site-packages/sqlalchemy/engine/default.py", line 686, in do_commit
    dbapi_connection.commit()
sqlalchemy.exc.OperationalError: (sqlite3.OperationalError) disk I/O error
(Background on this error at: https://sqlalche.me/e/14/e3q8)
[2025-01-28T08:21:14.103+0000] {taskinstance.py:1206} INFO - Marking task as UP_FOR_RETRY. dag_id=order_analysis_dag, task_id=load, run_id=scheduled__2024-06-18T00:00:00+00:00, execution_date=20240618T000000, start_date=20250128T082113, end_date=20250128T082114
[2025-01-28T08:21:14.113+0000] {standard_task_runner.py:110} ERROR - Failed to execute job 27 for task load ((sqlite3.OperationalError) disk I/O error
(Background on this error at: https://sqlalche.me/e/14/e3q8); 313)
[2025-01-28T08:21:14.151+0000] {local_task_job_runner.py:240} INFO - Task exited with return code 1
[2025-01-28T08:21:14.158+0000] {taskinstance.py:3498} INFO - 0 downstream tasks scheduled from follow-on schedule check
[2025-01-28T08:21:14.159+0000] {local_task_job_runner.py:222} INFO - ::endgroup::
